<mujoco model="panda">
  <compiler angle="radian" meshdir="assets/"/>

  <option timestep="0.001" solver="PGS" iterations="50"/>

  <default>
    <joint limited="true" armature="0.01" damping="0.01" frictionloss="0.01"/>
    <geom conaffinity="15" condim="4" friction="0.9 0.2 0.2" solref="0.001 2"/>

    <equality solref="0.001 2"/>
    <general ctrllimited="true"/>
    <default class="visualgeom">
      <geom contype="0" conaffinity="0" condim="1" material="visualgeom"/>
    </default>
  </default>

  <asset>
    <texture type="2d" name="texplane" builtin="checker" rgb1="0 0 0" rgb2="0.8 0.8 0.8" width="100" height="100"/>
    <material name="matplane" texture="texplane" texuniform="true"/>
    <material name="visualgeom" rgba="0.5 0.9 0.2 1"/>
    <mesh name="link0" file="link0.stl"/>
    <mesh name="link1" file="link1.stl"/>
    <mesh name="link2" file="link2.stl"/>
    <mesh name="link3" file="link3.stl"/>
    <mesh name="link4" file="link4.stl"/>
    <mesh name="link5" file="link5.stl"/>
    <mesh name="link6" file="link6.stl"/>
    <mesh name="link7" file="link7.stl"/>
  </asset>

  <worldbody>
    <geom name="ground" size="100 100 0.001" type="plane" condim="3" material="matplane"/>
    <camera name="fixed" pos="0 -3 0.580362" quat="0.707107 0.707107 0 0"/>
    <camera name="track" pos="0 -3 0.580362" quat="0.707107 0.707107 0 0" mode="trackcom"/>
    <light pos="0 0 5" dir="0 0 -1" directional="true" castshadow="false" diffuse="0.4 0.4 0.4" specular="0.1 0.1 0.1"/>
    <light pos="0 0 4" dir="0 0 -1" directional="true" diffuse="0.6 0.6 0.6" specular="0.2 0.2 0.2"/>
    <body name="root" pos="0 0 0.0803616">
      <geom class="visualgeom" type="mesh" contype="1" group="1" density="0" mesh="link0"/>
      <geom type="mesh" mesh="link0"/>
      <site name="imu" pos="0 0 0" size="0.01"/>
      <body name="link1" pos="0 0 0.333">
        <inertial pos="0.003875 0.002081 -0.175" quat="0.711549 0.00634377 -0.0131124 0.702485" mass="4.97068" diaginertia="0.707137 0.703435 0.00852456"/>
        <joint name="joint1" pos="0 0 0" axis="0 0 1" range="-2.8973 2.8973" actuatorfrcrange="-87 87" damping="10" frictionloss="5"/>
        <geom class="visualgeom" type="mesh" contype="1" group="1" density="0" mesh="link1"/>
        <geom type="mesh" mesh="link1"/>
        <body name="link2" quat="0.707107 -0.707107 0 0">
          <inertial pos="-0.003141 -0.02872 0.003495" quat="-0.168175 0.828366 -0.122878 0.520027" mass="0.646926" diaginertia="0.0310326 0.0283001 0.00273425"/>
          <joint name="joint2" pos="0 0 0" axis="0 0 1" range="-1.7628 1.7628" actuatorfrcrange="-87 87" damping="5" frictionloss="2"/>
          <geom class="visualgeom" type="mesh" contype="1" group="1" density="0" mesh="link2"/>
          <geom type="mesh" mesh="link2"/>
          <body name="link3" pos="0 -0.316 0" quat="0.707107 0.707107 0 0">
            <inertial pos="0.027518 0.039252 -0.066502" quat="0.662769 -0.00678331 0.252053 0.705096" mass="3.2286" diaginertia="0.0415014 0.0414793 0.00124635"/>
            <joint name="joint3" pos="0 0 0" axis="0 0 1" range="-2.8973 2.8973" actuatorfrcrange="-87 87" damping="5" frictionloss="2"/>
            <geom class="visualgeom" type="mesh" contype="1" group="1" density="0" mesh="link3"/>
            <geom type="mesh" mesh="link3"/>
            <body name="link4" pos="0.0825 0 0" quat="0.707107 0.707107 0 0">
              <inertial pos="-0.05317 0.104419 0.027454" quat="0.65058 0.529822 -0.0962034 0.535518" mass="3.5879" diaginertia="0.0349596 0.0281483 0.0106201"/>
              <joint name="joint4" pos="0 0 0" axis="0 0 1" range="-3.0718 -0.0698" actuatorfrcrange="-87 87" damping="1" frictionloss="0.5"/>
              <geom class="visualgeom" type="mesh" contype="1" group="1" density="0" mesh="link4"/>
              <geom type="mesh" mesh="link4"/>
              <body name="link5" pos="-0.0825 0.384 0" quat="0.707107 -0.707107 0 0">
                <inertial pos="-0.011953 0.041065 -0.038437" quat="0.987313 -0.0121954 0.0719187 -0.141037" mass="1.22595" diaginertia="0.0367625 0.0288531 0.00803437"/>
                <joint name="joint5" pos="0 0 0" axis="0 0 1" range="-2.8973 2.8973" actuatorfrcrange="-12 12" damping="2" frictionloss="1"/>
                <geom class="visualgeom" type="mesh" contype="1" group="1" density="0" mesh="link5"/>
                <geom type="mesh" mesh="link5"/>
                <body name="link6" quat="0.707107 0.707107 0 0">
                  <inertial pos="0.060149 -0.014117 -0.010517" quat="0.101075 0.59332 0.0287227 0.798079" mass="1.66656" diaginertia="0.00584276 0.00431037 0.00159787"/>
                  <joint name="joint6" pos="0 0 0" axis="0 0 1" range="-0.0175 3.7525" actuatorfrcrange="-12 12" damping="1" frictionloss="0.5"/>
                  <geom class="visualgeom" type="mesh" contype="1" group="1" density="0" mesh="link6"/>
                  <geom type="mesh" mesh="link6"/>
                  <body name="link7" pos="0.088 0 0" quat="0.707107 0.707107 0 0">
                    <inertial pos="0.010517 -0.004252 0.061597" quat="0.992939 -0.0762041 0.0733595 -0.0537067" mass="0.735522" diaginertia="0.0127345 0.0101055 0.00451803"/>
                    <joint name="joint7" pos="0 0 0" axis="0 0 1" range="-2.8973 2.8973" actuatorfrcrange="-12 12" damping="1" frictionloss="0.5"/>
                    <geom class="visualgeom" type="mesh" contype="1" group="1" density="0" mesh="link7"/>
                    <geom type="mesh" mesh="link7"/>
                  </body>
                </body>
              </body>
            </body>
          </body>
        </body>
      </body>
    </body>
  </worldbody>

  <actuator>
    <general name="joint1" joint="joint1" ctrlrange="-87 87"/>
    <general name="joint2" joint="joint2" ctrlrange="-87 87"/>
    <general name="joint3" joint="joint3" ctrlrange="-87 87"/>
    <general name="joint4" joint="joint4" ctrlrange="-87 87"/>
    <general name="joint5" joint="joint5" ctrlrange="-12 12"/>
    <general name="joint6" joint="joint6" ctrlrange="-12 12"/>
    <general name="joint7" joint="joint7" ctrlrange="-12 12"/>
  </actuator>

  <sensor>

    <actuatorpos actuator="joint1" name="joint1_p"/>

    <actuatorvel actuator="joint1" name="joint1_v"/>

    <actuatorfrc actuator="joint1" name="joint1_f" noise="0.001"/>

    <actuatorpos actuator="joint2" name="joint2_p"/>

    <actuatorvel actuator="joint2" name="joint2_v"/>

    <actuatorfrc actuator="joint2" name="joint2_f" noise="0.001"/>

    <actuatorpos actuator="joint3" name="joint3_p"/>

    <actuatorvel actuator="joint3" name="joint3_v"/>

    <actuatorfrc actuator="joint3" name="joint3_f" noise="0.001"/>

    <actuatorpos actuator="joint4" name="joint4_p"/>

    <actuatorvel actuator="joint4" name="joint4_v"/>

    <actuatorfrc actuator="joint4" name="joint4_f" noise="0.001"/>

    <actuatorpos actuator="joint5" name="joint5_p"/>

    <actuatorvel actuator="joint5" name="joint5_v"/>

    <actuatorfrc actuator="joint5" name="joint5_f" noise="0.001"/>

    <actuatorpos actuator="joint6" name="joint6_p"/>

    <actuatorvel actuator="joint6" name="joint6_v"/>

    <actuatorfrc actuator="joint6" name="joint6_f" noise="0.001"/>

    <actuatorpos actuator="joint7" name="joint7_p"/>

    <actuatorvel actuator="joint7" name="joint7_v"/>

    <actuatorfrc actuator="joint7" name="joint7_f" noise="0.001"/>
    <framequat objtype="site" objname="imu" name="orientation" noise="0.001"/>
    <gyro site="imu" name="angular-velocity" cutoff="34.9" noise="0.005"/>
  </sensor>
</mujoco>
